Workbook

Sheet Premissas
A1: Premissas — Business Plan MIPO
A2: Células amarelas = editáveis. Substitua pelos dados reais do case assim que disponíveis.
A4: Premissa | B4: Valor | C4: Nota
A6: Geral
A7: Pedidos por mês | B7: 1911 | C7: Dado real — 24.454 pedidos aprovados / 12,8 meses (jan/23–jan/24, 03_margem_e_issue_tree)
A9: Funcionalidade 1 — Orientação de tamanho (pré-venda)
A10: Compras/mês com risco de tamanho identificado | B10: 490 | C10: Dado real (piso) — 71 devoluções/mês por tamanho errado + 419 atendimentos/mês de Troca de Tamanho. Sem score individual de risco (ver nota metodológica)
A11: Taxa de aceite da recomendação | B11: 0.55 | C11: ASSUNÇÃO — recomendação ainda não existe; sem taxa de aceite observável
A12: Redução na devolução após aceite | B12: 0.3 | C12: ASSUNÇÃO — efeito da recomendação sobre devolução ainda não pode ser medido
A13: Frete reverso médio | B13: 22.5 | C13: ASSUNÇÃO — base não registra estorno, frete reverso ou custo pós-devolução
A14: Custo de reprocessamento médio | B14: 8 | C14: ASSUNÇÃO — base não registra custo de reprocessamento/reestoque
A15: Ticket médio (segmento tamanho) | B15: 674 | C15: Dado real — receita líquida média em pedidos devolvidos por tamanho errado (R$ 614.352 / 911 pedidos)
A16: Fator conservador — % das devoluções evitadas tratadas como venda salva | B16: 0.5 | C16: ASSUNÇÃO — fator de conservadorismo definido pela equipe, sem base empírica
A18: Funcionalidade 2 — Chatbot de status (pós-venda / WISMO)
A19: Atendimentos totais por mês (todos os canais) | B19: 2800 | C19: Dado real — 35.839 tickets válidos / 12,8 meses
A20: Atendimentos de rastreamento (WISMO) por mês | B20: 841 | C20: Dado real — 10.765 tickets 'Onde está meu pedido?' / 12,8 meses (30,0% do volume)
A21: % resolvido diretamente pelo bot | B21: 0.65 | C21: ASSUNÇÃO — chatbot ainda não existe. Coincide com a taxa de resolução humana atual (65,2%); tratar como piso, não meta
A22: Casos de atraso real dentro do WISMO | B22: 56 | C22: Dado real (proxy) — motivo de devolução 'Atraso na entrega': 711 pedidos / 12,8 meses. Não é um sub-tipo direto de ticket WISMO
A23: % que cancelaria/pediria estorno sem resposta proativa | B23: 0.08 | C23: ASSUNÇÃO — hipótese comportamental sem dado observável (contrafactual)
A24: Ticket médio (segmento WISMO) | B24: 724 | C24: Dado real — receita líquida média em pedidos ligados a tickets WISMO (R$ 2.224.339 / 3.071 pedidos)
A25: Margem de contribuição | B25: 0.543 | C25: Dado real — margem de contribuição aprovada / receita líquida aprovada (R$ 9.058.428 / R$ 16.668.956)
A27: Equipe de atendimento
A28: Atendentes atualmente alocados | B28: 6 | C28: ASSUNÇÃO — headcount não consta nas bases do case
A29: Custo mensal por atendente (salário + encargos) | B29: 6000 | C29: ASSUNÇÃO — custo de folha não consta nas bases do case
A30: Custo variável médio por atendimento | B30: 14.85 | C30: Dado real — custo operacional médio por ticket (R$ 532.260 / 35.840 tickets)
A32: Dimensionamento do desenvolvimento (investimento único)
A33: Engenharia de Dados — horas | B33: 240 | C33: h
A34: Engenharia de Dados — custo/hora | B34: 120 | C34: R$/h
A35: Ciência de Dados — horas | B35: 200 | C35: h
A36: Ciência de Dados — custo/hora | B36: 130 | C36: R$/h
A37: Engenharia de Produto — horas | B37: 220 | C37: h
A38: Engenharia de Produto — custo/hora | B38: 110 | C38: R$/h
A39: Gestão de Projeto — horas | B39: 120 | C39: h
A40: Gestão de Projeto — custo/hora | B40: 150 | C40: R$/h
A42: Manutenção recorrente (mensal)
A43: Engenharia de Dados — horas/mês manutenção | B43: 16 | C43: h/mês
A44: Ciência de Dados — horas/mês manutenção | B44: 12 | C44: h/mês
A45: Gestão — horas/mês manutenção | B45: 8 | C45: h/mês
A46: Infraestrutura e ferramentas | B46: 1500 | C46: R$/mês
A48: Fonte dos dados reais: notebooks 01_exploracao_inicial, 02_validacao_metodologica e 03_margem_e_issue_tree. Base validada: 24.454 pedidos aprovados, 35.839 tickets de atendimento, jan/2023–jan/2024 (13 meses, janeiro final parcial → dividido por 12,8 meses).
...

Sheet 1. Alternativas
A1: 1. Alternativas Consideradas
A2: Comparação entre os caminhos avaliados para resolver a mesma dor de negócio.
A4: Alternativa | B4: Impacto esperado | C4: Viabilidade técnica | D4: Custo de implementação | E4: Tempo de implementação | F4: Retorno / custo evitado
A5: A — Painel analítico manual (revisão manual, sem intervenção automática) | B5: Baixo | C5: Alta | D5: Baixo | E5: Curto | F5: Baixo
A6: B — Automação ponta a ponta (troca/reposição automática, integrada a ERP/WMS/TMS em tempo real) | B6: Alto | C6: Baixa | D6: Alto | E6: Longo (6+ meses) | F6: Alto, porém incerto
A7: C — Assistente em duas camadas: orientação de tamanho (pré-venda) + chatbot de status (pós-venda) [ESCOLHIDA] | B7: Alto | C7: Alta | D7: Médio | E7: Curto (≈ 8 semanas) | F7: Alto e rápido
A9: Justificativa: a alternativa C ataca os dois pontos de maior volume e menor complexidade de dados (devolução por tamanho e dúvida de rastreamento) sem depender de integração real com ERP/WMS/TMS — o que reduz custo e prazo frente à alternativa B, mantendo a decisão final com o cliente ou o atendente humano.

Sheet 2. Dimensionamento
A1: 2. Dimensionamento da Solução
A2: Horas-homem e custo de desenvolvimento por perfil profissional.
A4: Perfil | B4: Frente de trabalho | C4: Horas | D4: Custo/hora | E4: Custo total
A5: Engenharia de Dados | B5: Consolidação de bases, pipelines, APIs de risco e WISMO | C5: =Premissas!B33 -> 240 | D5: =Premissas!B34 -> 120 | E5: =C5*D5 -> 28800
A6: Ciência de Dados | B6: Motor de risco, motor de recomendação, regras WISMO, validação | C6: =Premissas!B35 -> 200 | D6: =Premissas!B36 -> 130 | E6: =C6*D6 -> 26000
A7: Engenharia de Produto | B7: Checkout inteligente (frontend) e chatbot (integração + UI) | C7: =Premissas!B37 -> 220 | D7: =Premissas!B38 -> 110 | E7: =C7*D7 -> 24200
A8: Gestão de Projeto | B8: Coordenação, priorização, validação funcional | C8: =Premissas!B39 -> 120 | D8: =Premissas!B40 -> 150 | E8: =C8*D8 -> 18000
A9: Total | C9: =SUM(C5:C8) -> 780 | D9: — | E9: =SUM(E5:E8) -> 97000
A11: Prazo estimado: ≈ 8 semanas (2 meses), com as quatro frentes trabalhando em paralelo a partir da 2ª semana.

Sheet 3. Manutenção
A1: 3. Custo de Manutenção
A2: Custo recorrente após o go-live.
A4: Item | B4: Frequência | C4: Horas/mês | D4: Custo/mês
A5: Engenharia de Dados — monitoramento de pipelines | B5: Contínua (automatizada) + revisão semanal | C5: =Premissas!B43 -> 16 | D5: =Premissas!B43*Premissas!B34 -> 1920
A6: Ciência de Dados — ajuste de regras/thresholds | B6: Revisão mensal, recalibração trimestral | C6: =Premissas!B44 -> 12 | D6: =Premissas!B44*Premissas!B36 -> 1560
A7: Gestão — acompanhamento de indicadores | B7: Mensal | C7: =Premissas!B45 -> 8 | D7: =Premissas!B45*Premissas!B40 -> 1200
A8: Infraestrutura e ferramentas (hosting, APIs, monitoramento) | B8: Recorrente | C8: — | D8: =Premissas!B46 -> 1500
A9: Total mensal | C9: =SUM(C5:C7) -> 36 | D9: =SUM(D5:D8) -> 6180
A10: Total anual | C10: — | D10: =D9*12 -> 74160

Sheet 4. Atendimento
A1: 4. Impacto no Atendimento
A2: Volume atual e fatia que o chatbot WISMO consegue absorver.
A4: Métrica | B4: Valor
A5: Atendimentos totais por mês | B5: =Premissas!B19 -> 2800
A6: Atendimentos de rastreamento (WISMO) por mês | B6: =Premissas!B20 -> 841
A7: % do volume total de atendimento | B7: =B6/B5 -> 0.30035714
A8: % dos pedidos/mês que geram contato WISMO | B8: =B6/Premissas!B7 -> 0.44008373
A9: % resolvido diretamente pelo bot | B9: =Premissas!B21 -> 0.65
A10: Atendimentos evitados por mês | B10: =B6*Premissas!B21 -> 546.65
A11: Redução no volume total de atendimento | B11: =B10/B5 -> 0.19523214

Sheet 5. Pessoal
A1: 5. Impacto sobre Custos de Pessoal
A2: Separação entre custo evitado real (caixa) e capacidade liberada (produtividade).
A4: Métrica | B4: Valor
A5: Atendentes atualmente alocados | B5: =Premissas!B28 -> 6
A6: Custo mensal por atendente (salário + encargos) | B6: =Premissas!B29 -> 6000
A7: Atendimentos por atendente/mês | B7: ='4. Atendimento'!B5/B5 -> 466.66667
A8: Custo variável médio por atendimento | B8: =Premissas!B30 -> 14.85
A10: Custo evitado real (caixa)
A11: Atendimentos evitados/mês (ref. aba 4) | B11: ='4. Atendimento'!B10 -> 546.65
A12: Custo evitado real (mensal) | B12: =B11*Premissas!B30 -> 8117.7525
A13: Este valor só vira economia completa se evitar hora extra, terceirização ou novas contratações.
A15: Capacidade liberada (não é corte de custo)
A16: Capacidade liberada (FTE equivalente) | B16: =B11/B7 -> 1.1713929
A17: Sem redução de headcount, é tempo redirecionável para casos complexos, upsell ou absorção de crescimento — não é linha de economia na DRE.

Sheet 6. Logística
A1: 6. Impacto Logístico
A2: Efeito da orientação de tamanho sobre a logística reversa.
A4: Etapa do cálculo | B4: Valor
A5: Compras/mês com risco de tamanho identificado | B5: =Premissas!B10 -> 490
A6: Taxa de aceite da recomendação | B6: =Premissas!B11 -> 0.55
A7: Redução na devolução após aceite | B7: =Premissas!B12 -> 0.3
A8: Devoluções evitadas/mês | B8: =Premissas!B10*Premissas!B11*Premissas!B12 -> 80.85
A9: Custo médio por devolução (frete reverso + reprocessamento) | B9: =Premissas!B13+Premissas!B14 -> 30.5
A10: Custo logístico evitado/mês | B10: =B8*B9 -> 2465.925
A11: Custo logístico evitado/ano | B11: =B10*12 -> 29591.1
A13: Outros impactos não quantificados: menor re-triagem em CD, menor ocupação de estoque reverso, menor risco de ruptura em SKUs presos no ciclo de devolução.

Sheet 7. Financeiro
A1: 7. Impacto Financeiro Consolidado
A2: Soma dos ganhos diretos das duas funcionalidades.
A4: Fonte de ganho | B4: Origem | C4: Valor mensal | D4: Valor anual
A5: Custo evitado com atendimento | B5: Chatbot WISMO — pós-venda | C5: ='5. Pessoal'!B12 -> 8117.7525 | D5: =C5*12 -> 97413.03
A6: Custo evitado com devoluções (logística) | B6: Orientação de tamanho — pré-venda | C6: ='6. Logística'!B10 -> 2465.925 | D6: =C6*12 -> 29591.1
A7: Margem protegida (retenção pós-venda) | B7: Chatbot WISMO — cancelamentos evitados | C7: ='8. Margem'!B10 -> 1761.2314 | D7: =C7*12 -> 21134.776
A8: Margem adicional (retenção pré-venda) | B8: Orientação de tamanho — vendas mantidas | C8: ='8. Margem'!B15 -> 14794.822 | D8: =C8*12 -> 177537.87
A9: TOTAL (direto) | C9: =SUM(C5:C8) -> 27139.731 | D9: =SUM(D5:D8) -> 325676.77
A11: A capacidade liberada (aba 5) não entra nesta soma — é ganho de produtividade, não fluxo de caixa direto.

Sheet 8. Margem
A1: 8. Ganho de Margem
A2: Detalhamento do componente de margem dentro do impacto financeiro total.
A4: Métrica | B4: Valor
A5: Margem protegida — pós-venda (Chatbot WISMO)
A6: Casos de atraso real/mês | B6: =Premissas!B22 -> 56
A7: % que cancelaria sem resposta proativa | B7: =Premissas!B23 -> 0.08
A8: Cancelamentos evitados/mês | B8: =B6*B7 -> 4.48
A9: Ticket médio (WISMO) × margem de contribuição | B9: =Premissas!B24*Premissas!B25 -> 393.132
A10: Margem protegida (mensal) | B10: =B8*B9 -> 1761.2314
A12: Margem adicional — pré-venda (Orientação de tamanho)
A13: Devoluções evitadas/mês (ref. aba 6) | B13: ='6. Logística'!B8 -> 80.85
A14: Base conservadora (fator de venda salva) | B14: =B13*Premissas!B16 -> 40.425
A15: Margem adicional (mensal) | B15: =B14*Premissas!B15*Premissas!B25 -> 14794.822
A17: Margem incremental total
A18: Total mensal | B18: =B10+B15 -> 16556.054
A19: Total anual | B19: =B18*12 -> 198672.64
A21: Fator conservador aplicado às devoluções evitadas para não contar como 'venda salva' os casos que resultariam em troca (e não em perda total).

Sheet 9. Business Case
A1: 9. Business Case — Investimento vs. Retorno
A2: Consolidação final: investimento total contra benefício gerado, com payback e ROI.
A4: Investimento | B4: Valor
A5: Desenvolvimento (único) | B5: ='2. Dimensionamento'!E9 -> 97000
A6: Manutenção (ano 1) | B6: ='3. Manutenção'!D10 -> 74160
A7: Total investimento ano 1 | B7: =B5+B6 -> 171160
A9: Benefício | B9: Valor
A10: Custo evitado (atendimento + logística) | B10: ='7. Financeiro'!D5+'7. Financeiro'!D6 -> 127004.13
A11: Margem incremental (ano 1) | B11: ='8. Margem'!B19 -> 198672.64
A12: Total benefício ano 1 (run-rate) | B12: ='7. Financeiro'!D9 -> 325676.77
A14: Indicador | B14: Valor
A15: Benefício líquido ano 1 | B15: =B12-B7 -> 154516.77
A16: ROI ano 1 | B16: =(B12-B7)/B7 -> 0.90276218
A17: Payback (meses, sobre desenvolvimento) | B17: =B5/'7. Financeiro'!C9 -> 3.5740958
A18: Capacidade liberada (não monetizada, FTE) | B18: ='5. Pessoal'!B16 -> 1.1713929
A20: Ressalva de ramp-up: os valores assumem taxa de aceite e resolução do bot já maduras desde o mês 1. Na prática esses números crescem nos primeiros 2–3 meses — o payback real provavelmente fica entre 3 e 4 meses. Estimativas de potencial, a validar com piloto controlado.
